2024-02-16 13:31:41,110 INFO    MainThread:65124 [wandb_setup.py:_flush():69] setting env: {}
2024-02-16 13:31:41,110 INFO    MainThread:65124 [wandb_setup.py:_flush():69] setting login settings: {}
2024-02-16 13:31:41,111 INFO    MainThread:65124 [wandb_init.py:_log_setup():342] Logging user logs to C:\Users\Mahra\Desktop\Projects\Thesis\Chapter 6 Advanced MemoryManagementBPTT\wandb\run-20240216_133141-10etrgjv\logs\debug.log
2024-02-16 13:31:41,111 INFO    MainThread:65124 [wandb_init.py:_log_setup():343] Logging internal logs to C:\Users\Mahra\Desktop\Projects\Thesis\Chapter 6 Advanced MemoryManagementBPTT\wandb\run-20240216_133141-10etrgjv\logs\debug-internal.log
2024-02-16 13:31:41,111 INFO    MainThread:65124 [wandb_init.py:init():375] calling init triggers
2024-02-16 13:31:41,111 INFO    MainThread:65124 [wandb_init.py:init():380] wandb.init called with sweep_config: {}
config: {'randomised_heights': True, 'memory_modification_type': 'No_memory', 'sensor_distance': 0, 'dimenstional_information': 3, 'number_of_sensors': 1, 'num_memory_nodes': 0, 'sensor_is_directable': False, 'action_network_sees_xy_position': False, 'randomised_food_location': True, 'sees_highest_points': False, 'sees_direction_to_highest': False, 'neural_layers': [12, 12], 'num_food': 1, 'batch_size': 100, 'trajectory_length': 30, 'max_iteration': 100000, 'slow_start': False, 'learning_rate': 0.001, 'randomise_start_of_iterations': True, 'shortcuts': False}
2024-02-16 13:31:41,111 INFO    MainThread:65124 [wandb_init.py:init():424] starting backend
2024-02-16 13:31:41,111 INFO    MainThread:65124 [backend.py:_multiprocessing_setup():70] multiprocessing start_methods=spawn, using: spawn
2024-02-16 13:31:41,118 INFO    MainThread:65124 [backend.py:ensure_launched():135] starting backend process...
2024-02-16 13:31:41,318 INFO    MainThread:65124 [backend.py:ensure_launched():139] started backend process with pid: 39124
2024-02-16 13:31:41,319 INFO    MainThread:65124 [wandb_init.py:init():429] backend started and connected
2024-02-16 13:31:41,320 INFO    MainThread:65124 [wandb_init.py:init():477] updated telemetry
2024-02-16 13:31:41,320 INFO    MainThread:65124 [wandb_init.py:init():500] communicating current version
2024-02-16 13:31:42,463 INFO    MainThread:65124 [wandb_init.py:init():505] got version response upgrade_message: "wandb version 0.16.3 is available!  To upgrade, please run:\n $ pip install wandb --upgrade"

2024-02-16 13:31:42,463 INFO    MainThread:65124 [wandb_init.py:init():513] communicating run to backend with 30 second timeout
2024-02-16 13:31:42,721 INFO    MainThread:65124 [wandb_init.py:init():540] starting run threads in backend
2024-02-16 13:31:45,203 INFO    MainThread:65124 [wandb_run.py:_console_start():1584] atexit reg
2024-02-16 13:31:45,203 INFO    MainThread:65124 [wandb_run.py:_redirect():1458] redirect: SettingsConsole.WRAP
2024-02-16 13:31:45,204 INFO    MainThread:65124 [wandb_run.py:_redirect():1495] Wrapping output streams.
2024-02-16 13:31:45,204 INFO    MainThread:65124 [wandb_run.py:_redirect():1519] Redirects installed.
2024-02-16 13:31:45,205 INFO    MainThread:65124 [wandb_init.py:init():565] run started, returning control to user process
2024-02-16 13:42:14,040 ERROR   MainThread:65124 [util.py:get_module():180] Error importing optional module plotly.tools
Traceback (most recent call last):
  File "C:\Users\Mahra\AppData\Local\Packages\PythonSoftwareFoundation.Python.3.8_qbz5n2kfra8p0\LocalCache\local-packages\Python38\site-packages\wandb\util.py", line 175, in get_module
    return import_module(name)
  File "C:\Program Files\WindowsApps\PythonSoftwareFoundation.Python.3.8_3.8.2800.0_x64__qbz5n2kfra8p0\lib\importlib\__init__.py", line 127, in import_module
    return _bootstrap._gcd_import(name[level:], package, level)
  File "<frozen importlib._bootstrap>", line 1014, in _gcd_import
  File "<frozen importlib._bootstrap>", line 991, in _find_and_load
  File "<frozen importlib._bootstrap>", line 961, in _find_and_load_unlocked
  File "<frozen importlib._bootstrap>", line 219, in _call_with_frames_removed
  File "<frozen importlib._bootstrap>", line 1014, in _gcd_import
  File "<frozen importlib._bootstrap>", line 991, in _find_and_load
  File "<frozen importlib._bootstrap>", line 973, in _find_and_load_unlocked
ModuleNotFoundError: No module named 'plotly'
2024-02-16 13:42:14,054 INFO    MainThread:65124 [wandb_run.py:_atexit_cleanup():1554] got exitcode: 1
2024-02-16 13:42:14,055 INFO    MainThread:65124 [wandb_run.py:_restore():1526] restore
2024-02-16 13:42:17,906 ERROR   MainThread:65124 [wandb_run.py:_atexit_cleanup():1572] Problem finishing run
Traceback (most recent call last):
  File "C:\Users\Mahra\AppData\Local\Packages\PythonSoftwareFoundation.Python.3.8_qbz5n2kfra8p0\LocalCache\local-packages\Python38\site-packages\wandb\sdk\wandb_run.py", line 1562, in _atexit_cleanup
    self._on_finish()
  File "C:\Users\Mahra\AppData\Local\Packages\PythonSoftwareFoundation.Python.3.8_qbz5n2kfra8p0\LocalCache\local-packages\Python38\site-packages\wandb\sdk\wandb_run.py", line 1698, in _on_finish
    self.history._flush()
  File "C:\Users\Mahra\AppData\Local\Packages\PythonSoftwareFoundation.Python.3.8_qbz5n2kfra8p0\LocalCache\local-packages\Python38\site-packages\wandb\sdk\wandb_history.py", line 59, in _flush
    self._callback(row=self._data, step=self._step)
  File "C:\Users\Mahra\AppData\Local\Packages\PythonSoftwareFoundation.Python.3.8_qbz5n2kfra8p0\LocalCache\local-packages\Python38\site-packages\wandb\sdk\wandb_run.py", line 885, in _history_callback
    self._backend.interface.publish_history(
  File "C:\Users\Mahra\AppData\Local\Packages\PythonSoftwareFoundation.Python.3.8_qbz5n2kfra8p0\LocalCache\local-packages\Python38\site-packages\wandb\sdk\interface\interface.py", line 214, in publish_history
    data = data_types.history_dict_to_json(run, data, step=step)
  File "C:\Users\Mahra\AppData\Local\Packages\PythonSoftwareFoundation.Python.3.8_qbz5n2kfra8p0\LocalCache\local-packages\Python38\site-packages\wandb\sdk\data_types.py", line 2318, in history_dict_to_json
    payload[key] = val_to_json(run, key, val, namespace=step)
  File "C:\Users\Mahra\AppData\Local\Packages\PythonSoftwareFoundation.Python.3.8_qbz5n2kfra8p0\LocalCache\local-packages\Python38\site-packages\wandb\sdk\data_types.py", line 2343, in val_to_json
    val = Plotly.make_plot_media(val)
  File "C:\Users\Mahra\AppData\Local\Packages\PythonSoftwareFoundation.Python.3.8_qbz5n2kfra8p0\LocalCache\local-packages\Python38\site-packages\wandb\sdk\data_types.py", line 2268, in make_plot_media
    val = util.matplotlib_to_plotly(val)
  File "C:\Users\Mahra\AppData\Local\Packages\PythonSoftwareFoundation.Python.3.8_qbz5n2kfra8p0\LocalCache\local-packages\Python38\site-packages\wandb\util.py", line 413, in matplotlib_to_plotly
    tools = get_module(
  File "C:\Users\Mahra\AppData\Local\Packages\PythonSoftwareFoundation.Python.3.8_qbz5n2kfra8p0\LocalCache\local-packages\Python38\site-packages\wandb\util.py", line 182, in get_module
    raise wandb.Error(required)
wandb.errors.Error: plotly is required to log interactive plots, install with: pip install plotly or convert the plot to an image with `wandb.Image(plt)`
