Traceback (most recent call last):
  File "C:/Users/Mahra/Desktop/Projects/Thesis/Chapter 6 Advanced MemoryManagementBPTT/experiment.py", line 189, in <module>
    [average_total_reward,trajectories] = expand_full_trajectory( environment.initial_state, environment.food_location)
  File "C:\Users\Mahra\AppData\Local\Packages\PythonSoftwareFoundation.Python.3.8_qbz5n2kfra8p0\LocalCache\local-packages\Python38\site-packages\tensorflow\python\util\traceback_utils.py", line 153, in error_handler
    raise e.with_traceback(filtered_tb) from None
  File "C:\Users\Mahra\AppData\Local\Temp\__autograph_generated_filezsygg7fj.py", line 32, in tf__expand_full_trajectory
    ag__.for_stmt(ag__.converted_call(ag__.ld(range), (ag__.ld(trajectory_length),), None, fscope), None, loop_body, get_state, set_state, ('total_rewards', 'state'), {'iterate_names': 'time_step'})
  File "C:\Users\Mahra\AppData\Local\Temp\__autograph_generated_filezsygg7fj.py", line 24, in loop_body
    action = ag__.converted_call(ag__.ld(keras_ant_brain), (ag__.converted_call(ag__.ld(convert_state), (ag__.ld(state),), None, fscope),), None, fscope)
  File "C:\Users\Mahra\AppData\Local\Temp\__autograph_generated_files1_8sfrz.py", line 54, in tf__convert_state
    retval_ = ag__.ld(converted_state)
UnboundLocalError: in user code:
    File "C:/Users/Mahra/Desktop/Projects/Thesis/Chapter 6 Advanced MemoryManagementBPTT/experiment.py", line 180, in expand_full_trajectory  *
        action = keras_ant_brain(convert_state(state))
    File "C:/Users/Mahra/Desktop/Projects/Thesis/Chapter 6 Advanced MemoryManagementBPTT/experiment.py", line 172, in convert_state  *
        return converted_state
    UnboundLocalError: 'converted_state' is used before assignment